2025-10-23 14:21:12,316 - f2 - ERROR - Traceback (most recent call last):
  File "e:\python_project\chrome_plugin\venv\Lib\site-packages\httpx\_transports\default.py", line 72, in map_httpcore_exceptions
    yield
  File "e:\python_project\chrome_plugin\venv\Lib\site-packages\httpx\_transports\default.py", line 236, in handle_request
    resp = self._pool.handle_request(req)
  File "e:\python_project\chrome_plugin\venv\Lib\site-packages\httpcore\_sync\connection_pool.py", line 256, in handle_request
    raise exc from None
  File "e:\python_project\chrome_plugin\venv\Lib\site-packages\httpcore\_sync\connection_pool.py", line 236, in handle_request
    response = connection.handle_request(
        pool_request.request
    )
  File "e:\python_project\chrome_plugin\venv\Lib\site-packages\httpcore\_sync\http_proxy.py", line 288, in handle_request
    connect_response = self._connection.handle_request(
        connect_request
    )
  File "e:\python_project\chrome_plugin\venv\Lib\site-packages\httpcore\_sync\connection.py", line 101, in handle_request
    raise exc
  File "e:\python_project\chrome_plugin\venv\Lib\site-packages\httpcore\_sync\connection.py", line 78, in handle_request
    stream = self._connect(request)
  File "e:\python_project\chrome_plugin\venv\Lib\site-packages\httpcore\_sync\connection.py", line 124, in _connect
    stream = self._network_backend.connect_tcp(**kwargs)
  File "e:\python_project\chrome_plugin\venv\Lib\site-packages\httpcore\_backends\sync.py", line 207, in connect_tcp
    with map_exceptions(exc_map):
         ~~~~~~~~~~~~~~^^^^^^^^^
  File "C:\Python313\Lib\contextlib.py", line 162, in __exit__
    self.gen.throw(value)
    ~~~~~~~~~~~~~~^^^^^^^
  File "e:\python_project\chrome_plugin\venv\Lib\site-packages\httpcore\_exceptions.py", line 14, in map_exceptions
    raise to_exc(exc) from exc
httpcore.ConnectError: [WinError 10061] 由于目标计算机积极拒绝，无法连接。

The above exception was the direct cause of the following exception:

Traceback (most recent call last):
  File "e:\python_project\chrome_plugin\venv\Lib\site-packages\f2\apps\douyin\utils.py", line 213, in gen_real_msToken
    response = instance.client.post(
        instance.token_conf["url"],
        content=payload,
        headers=instance.mstoken_headers,
    )
  File "e:\python_project\chrome_plugin\venv\Lib\site-packages\httpx\_client.py", line 1157, in post
    return self.request(
           ~~~~~~~~~~~~^
        "POST",
        ^^^^^^^
    ...<11 lines>...
        extensions=extensions,
        ^^^^^^^^^^^^^^^^^^^^^^
    )
    ^
  File "e:\python_project\chrome_plugin\venv\Lib\site-packages\httpx\_client.py", line 837, in request
    return self.send(request, auth=auth, follow_redirects=follow_redirects)
           ~~~~~~~~~^^^^^^^^^^^^^^^^^^^^^^^^^^^^^^^^^^^^^^^^^^^^^^^^^^^^^^^
  File "e:\python_project\chrome_plugin\venv\Lib\site-packages\httpx\_client.py", line 926, in send
    response = self._send_handling_auth(
        request,
    ...<2 lines>...
        history=[],
    )
  File "e:\python_project\chrome_plugin\venv\Lib\site-packages\httpx\_client.py", line 954, in _send_handling_auth
    response = self._send_handling_redirects(
        request,
        follow_redirects=follow_redirects,
        history=history,
    )
  File "e:\python_project\chrome_plugin\venv\Lib\site-packages\httpx\_client.py", line 991, in _send_handling_redirects
    response = self._send_single_request(request)
  File "e:\python_project\chrome_plugin\venv\Lib\site-packages\httpx\_client.py", line 1027, in _send_single_request
    response = transport.handle_request(request)
  File "e:\python_project\chrome_plugin\venv\Lib\site-packages\httpx\_transports\default.py", line 235, in handle_request
    with map_httpcore_exceptions():
         ~~~~~~~~~~~~~~~~~~~~~~~^^
  File "C:\Python313\Lib\contextlib.py", line 162, in __exit__
    self.gen.throw(value)
    ~~~~~~~~~~~~~~^^^^^^^
  File "e:\python_project\chrome_plugin\venv\Lib\site-packages\httpx\_transports\default.py", line 89, in map_httpcore_exceptions
    raise mapped_exc(message) from exc
httpx.ConnectError: [WinError 10061] 由于目标计算机积极拒绝，无法连接。

2025-10-23 14:21:12,336 - f2 - ERROR - 请前往QA文档 https://f2.wiki/faq 查看相关帮助
2025-10-23 14:21:15,224 - f2 - ERROR - Traceback (most recent call last):
  File "e:\python_project\chrome_plugin\venv\Lib\site-packages\httpx\_transports\default.py", line 72, in map_httpcore_exceptions
    yield
  File "e:\python_project\chrome_plugin\venv\Lib\site-packages\httpx\_transports\default.py", line 236, in handle_request
    resp = self._pool.handle_request(req)
  File "e:\python_project\chrome_plugin\venv\Lib\site-packages\httpcore\_sync\connection_pool.py", line 256, in handle_request
    raise exc from None
  File "e:\python_project\chrome_plugin\venv\Lib\site-packages\httpcore\_sync\connection_pool.py", line 236, in handle_request
    response = connection.handle_request(
        pool_request.request
    )
  File "e:\python_project\chrome_plugin\venv\Lib\site-packages\httpcore\_sync\http_proxy.py", line 288, in handle_request
    connect_response = self._connection.handle_request(
        connect_request
    )
  File "e:\python_project\chrome_plugin\venv\Lib\site-packages\httpcore\_sync\connection.py", line 101, in handle_request
    raise exc
  File "e:\python_project\chrome_plugin\venv\Lib\site-packages\httpcore\_sync\connection.py", line 78, in handle_request
    stream = self._connect(request)
  File "e:\python_project\chrome_plugin\venv\Lib\site-packages\httpcore\_sync\connection.py", line 124, in _connect
    stream = self._network_backend.connect_tcp(**kwargs)
  File "e:\python_project\chrome_plugin\venv\Lib\site-packages\httpcore\_backends\sync.py", line 207, in connect_tcp
    with map_exceptions(exc_map):
         ~~~~~~~~~~~~~~^^^^^^^^^
  File "C:\Python313\Lib\contextlib.py", line 162, in __exit__
    self.gen.throw(value)
    ~~~~~~~~~~~~~~^^^^^^^
  File "e:\python_project\chrome_plugin\venv\Lib\site-packages\httpcore\_exceptions.py", line 14, in map_exceptions
    raise to_exc(exc) from exc
httpcore.ConnectError: [WinError 10061] 由于目标计算机积极拒绝，无法连接。

The above exception was the direct cause of the following exception:

Traceback (most recent call last):
  File "e:\python_project\chrome_plugin\venv\Lib\site-packages\f2\apps\douyin\utils.py", line 213, in gen_real_msToken
    response = instance.client.post(
        instance.token_conf["url"],
        content=payload,
        headers=instance.mstoken_headers,
    )
  File "e:\python_project\chrome_plugin\venv\Lib\site-packages\httpx\_client.py", line 1157, in post
    return self.request(
           ~~~~~~~~~~~~^
        "POST",
        ^^^^^^^
    ...<11 lines>...
        extensions=extensions,
        ^^^^^^^^^^^^^^^^^^^^^^
    )
    ^
  File "e:\python_project\chrome_plugin\venv\Lib\site-packages\httpx\_client.py", line 837, in request
    return self.send(request, auth=auth, follow_redirects=follow_redirects)
           ~~~~~~~~~^^^^^^^^^^^^^^^^^^^^^^^^^^^^^^^^^^^^^^^^^^^^^^^^^^^^^^^
  File "e:\python_project\chrome_plugin\venv\Lib\site-packages\httpx\_client.py", line 926, in send
    response = self._send_handling_auth(
        request,
    ...<2 lines>...
        history=[],
    )
  File "e:\python_project\chrome_plugin\venv\Lib\site-packages\httpx\_client.py", line 954, in _send_handling_auth
    response = self._send_handling_redirects(
        request,
        follow_redirects=follow_redirects,
        history=history,
    )
  File "e:\python_project\chrome_plugin\venv\Lib\site-packages\httpx\_client.py", line 991, in _send_handling_redirects
    response = self._send_single_request(request)
  File "e:\python_project\chrome_plugin\venv\Lib\site-packages\httpx\_client.py", line 1027, in _send_single_request
    response = transport.handle_request(request)
  File "e:\python_project\chrome_plugin\venv\Lib\site-packages\httpx\_transports\default.py", line 235, in handle_request
    with map_httpcore_exceptions():
         ~~~~~~~~~~~~~~~~~~~~~~~^^
  File "C:\Python313\Lib\contextlib.py", line 162, in __exit__
    self.gen.throw(value)
    ~~~~~~~~~~~~~~^^^^^^^
  File "e:\python_project\chrome_plugin\venv\Lib\site-packages\httpx\_transports\default.py", line 89, in map_httpcore_exceptions
    raise mapped_exc(message) from exc
httpx.ConnectError: [WinError 10061] 由于目标计算机积极拒绝，无法连接。

2025-10-23 14:21:15,230 - f2 - ERROR - 请前往QA文档 https://f2.wiki/faq 查看相关帮助
