2025-10-23 01:54:17,602 - f2 - ERROR - Traceback (most recent call last):
  File "e:\python_project\chrome_plugin\venv\Lib\site-packages\httpx\_transports\default.py", line 72, in map_httpcore_exceptions
    yield
  File "e:\python_project\chrome_plugin\venv\Lib\site-packages\httpx\_transports\default.py", line 377, in handle_async_request
    resp = await self._pool.handle_async_request(req)
           ^^^^^^^^^^^^^^^^^^^^^^^^^^^^^^^^^^^^^^^^^^
  File "e:\python_project\chrome_plugin\venv\Lib\site-packages\httpcore\_async\connection_pool.py", line 207, in handle_async_request
    raise UnsupportedProtocol(
        "Request URL is missing an 'http://' or 'https://' protocol."
    )
httpcore.UnsupportedProtocol: Request URL is missing an 'http://' or 'https://' protocol.

The above exception was the direct cause of the following exception:

Traceback (most recent call last):
  File "e:\python_project\chrome_plugin\venv\Lib\site-packages\f2\utils\_dl.py", line 40, in get_content_length
    response = await aclient.head(url, headers=headers, follow_redirects=True)
               ^^^^^^^^^^^^^^^^^^^^^^^^^^^^^^^^^^^^^^^^^^^^^^^^^^^^^^^^^^^^^^^
  File "e:\python_project\chrome_plugin\venv\Lib\site-packages\httpx\_client.py", line 1872, in head
    return await self.request(
           ^^^^^^^^^^^^^^^^^^^
    ...<9 lines>...
    )
    ^
  File "e:\python_project\chrome_plugin\venv\Lib\site-packages\httpx\_client.py", line 1585, in request
    return await self.send(request, auth=auth, follow_redirects=follow_redirects)
           ^^^^^^^^^^^^^^^^^^^^^^^^^^^^^^^^^^^^^^^^^^^^^^^^^^^^^^^^^^^^^^^^^^^^^^
  File "e:\python_project\chrome_plugin\venv\Lib\site-packages\httpx\_client.py", line 1674, in send
    response = await self._send_handling_auth(
               ^^^^^^^^^^^^^^^^^^^^^^^^^^^^^^^
    ...<4 lines>...
    )
    ^
  File "e:\python_project\chrome_plugin\venv\Lib\site-packages\httpx\_client.py", line 1702, in _send_handling_auth
    response = await self._send_handling_redirects(
               ^^^^^^^^^^^^^^^^^^^^^^^^^^^^^^^^^^^^
    ...<3 lines>...
    )
    ^
  File "e:\python_project\chrome_plugin\venv\Lib\site-packages\httpx\_client.py", line 1739, in _send_handling_redirects
    response = await self._send_single_request(request)
               ^^^^^^^^^^^^^^^^^^^^^^^^^^^^^^^^^^^^^^^^
  File "e:\python_project\chrome_plugin\venv\Lib\site-packages\httpx\_client.py", line 1776, in _send_single_request
    response = await transport.handle_async_request(request)
               ^^^^^^^^^^^^^^^^^^^^^^^^^^^^^^^^^^^^^^^^^^^^^
  File "e:\python_project\chrome_plugin\venv\Lib\site-packages\httpx\_transports\default.py", line 376, in handle_async_request
    with map_httpcore_exceptions():
         ~~~~~~~~~~~~~~~~~~~~~~~^^
  File "C:\Python313\Lib\contextlib.py", line 162, in __exit__
    self.gen.throw(value)
    ~~~~~~~~~~~~~~^^^^^^^
  File "e:\python_project\chrome_plugin\venv\Lib\site-packages\httpx\_transports\default.py", line 89, in map_httpcore_exceptions
    raise mapped_exc(message) from exc
httpx.UnsupportedProtocol: Request URL is missing an 'http://' or 'https://' protocol.

2025-10-23 01:54:17,620 - f2 - ERROR - httpx 请求错误：data_size，错误详情：Request URL is missing an 'http://' or 'https://' protocol.
2025-10-23 01:54:17,622 - f2 - WARNING - 链接 data_size 响应大小为 0 字节，尝试下一个链接是否可用
2025-10-23 01:54:17,913 - f2 - ERROR - Traceback (most recent call last):
  File "e:\python_project\chrome_plugin\venv\Lib\site-packages\httpx\_transports\default.py", line 72, in map_httpcore_exceptions
    yield
  File "e:\python_project\chrome_plugin\venv\Lib\site-packages\httpx\_transports\default.py", line 377, in handle_async_request
    resp = await self._pool.handle_async_request(req)
           ^^^^^^^^^^^^^^^^^^^^^^^^^^^^^^^^^^^^^^^^^^
  File "e:\python_project\chrome_plugin\venv\Lib\site-packages\httpcore\_async\connection_pool.py", line 207, in handle_async_request
    raise UnsupportedProtocol(
        "Request URL is missing an 'http://' or 'https://' protocol."
    )
httpcore.UnsupportedProtocol: Request URL is missing an 'http://' or 'https://' protocol.

The above exception was the direct cause of the following exception:

Traceback (most recent call last):
  File "e:\python_project\chrome_plugin\venv\Lib\site-packages\f2\utils\_dl.py", line 40, in get_content_length
    response = await aclient.head(url, headers=headers, follow_redirects=True)
               ^^^^^^^^^^^^^^^^^^^^^^^^^^^^^^^^^^^^^^^^^^^^^^^^^^^^^^^^^^^^^^^
  File "e:\python_project\chrome_plugin\venv\Lib\site-packages\httpx\_client.py", line 1872, in head
    return await self.request(
           ^^^^^^^^^^^^^^^^^^^
    ...<9 lines>...
    )
    ^
  File "e:\python_project\chrome_plugin\venv\Lib\site-packages\httpx\_client.py", line 1585, in request
    return await self.send(request, auth=auth, follow_redirects=follow_redirects)
           ^^^^^^^^^^^^^^^^^^^^^^^^^^^^^^^^^^^^^^^^^^^^^^^^^^^^^^^^^^^^^^^^^^^^^^
  File "e:\python_project\chrome_plugin\venv\Lib\site-packages\httpx\_client.py", line 1674, in send
    response = await self._send_handling_auth(
               ^^^^^^^^^^^^^^^^^^^^^^^^^^^^^^^
    ...<4 lines>...
    )
    ^
  File "e:\python_project\chrome_plugin\venv\Lib\site-packages\httpx\_client.py", line 1702, in _send_handling_auth
    response = await self._send_handling_redirects(
               ^^^^^^^^^^^^^^^^^^^^^^^^^^^^^^^^^^^^
    ...<3 lines>...
    )
    ^
  File "e:\python_project\chrome_plugin\venv\Lib\site-packages\httpx\_client.py", line 1739, in _send_handling_redirects
    response = await self._send_single_request(request)
               ^^^^^^^^^^^^^^^^^^^^^^^^^^^^^^^^^^^^^^^^
  File "e:\python_project\chrome_plugin\venv\Lib\site-packages\httpx\_client.py", line 1776, in _send_single_request
    response = await transport.handle_async_request(request)
               ^^^^^^^^^^^^^^^^^^^^^^^^^^^^^^^^^^^^^^^^^^^^^
  File "e:\python_project\chrome_plugin\venv\Lib\site-packages\httpx\_transports\default.py", line 376, in handle_async_request
    with map_httpcore_exceptions():
         ~~~~~~~~~~~~~~~~~~~~~~~^^
  File "C:\Python313\Lib\contextlib.py", line 162, in __exit__
    self.gen.throw(value)
    ~~~~~~~~~~~~~~^^^^^^^
  File "e:\python_project\chrome_plugin\venv\Lib\site-packages\httpx\_transports\default.py", line 89, in map_httpcore_exceptions
    raise mapped_exc(message) from exc
httpx.UnsupportedProtocol: Request URL is missing an 'http://' or 'https://' protocol.

2025-10-23 01:54:17,917 - f2 - ERROR - httpx 请求错误：file_cs，错误详情：Request URL is missing an 'http://' or 'https://' protocol.
2025-10-23 01:54:17,919 - f2 - WARNING - 链接 file_cs 响应大小为 0 字节，尝试下一个链接是否可用
2025-10-23 01:54:18,209 - f2 - ERROR - Traceback (most recent call last):
  File "e:\python_project\chrome_plugin\venv\Lib\site-packages\httpx\_transports\default.py", line 72, in map_httpcore_exceptions
    yield
  File "e:\python_project\chrome_plugin\venv\Lib\site-packages\httpx\_transports\default.py", line 377, in handle_async_request
    resp = await self._pool.handle_async_request(req)
           ^^^^^^^^^^^^^^^^^^^^^^^^^^^^^^^^^^^^^^^^^^
  File "e:\python_project\chrome_plugin\venv\Lib\site-packages\httpcore\_async\connection_pool.py", line 207, in handle_async_request
    raise UnsupportedProtocol(
        "Request URL is missing an 'http://' or 'https://' protocol."
    )
httpcore.UnsupportedProtocol: Request URL is missing an 'http://' or 'https://' protocol.

The above exception was the direct cause of the following exception:

Traceback (most recent call last):
  File "e:\python_project\chrome_plugin\venv\Lib\site-packages\f2\utils\_dl.py", line 40, in get_content_length
    response = await aclient.head(url, headers=headers, follow_redirects=True)
               ^^^^^^^^^^^^^^^^^^^^^^^^^^^^^^^^^^^^^^^^^^^^^^^^^^^^^^^^^^^^^^^
  File "e:\python_project\chrome_plugin\venv\Lib\site-packages\httpx\_client.py", line 1872, in head
    return await self.request(
           ^^^^^^^^^^^^^^^^^^^
    ...<9 lines>...
    )
    ^
  File "e:\python_project\chrome_plugin\venv\Lib\site-packages\httpx\_client.py", line 1585, in request
    return await self.send(request, auth=auth, follow_redirects=follow_redirects)
           ^^^^^^^^^^^^^^^^^^^^^^^^^^^^^^^^^^^^^^^^^^^^^^^^^^^^^^^^^^^^^^^^^^^^^^
  File "e:\python_project\chrome_plugin\venv\Lib\site-packages\httpx\_client.py", line 1674, in send
    response = await self._send_handling_auth(
               ^^^^^^^^^^^^^^^^^^^^^^^^^^^^^^^
    ...<4 lines>...
    )
    ^
  File "e:\python_project\chrome_plugin\venv\Lib\site-packages\httpx\_client.py", line 1702, in _send_handling_auth
    response = await self._send_handling_redirects(
               ^^^^^^^^^^^^^^^^^^^^^^^^^^^^^^^^^^^^
    ...<3 lines>...
    )
    ^
  File "e:\python_project\chrome_plugin\venv\Lib\site-packages\httpx\_client.py", line 1739, in _send_handling_redirects
    response = await self._send_single_request(request)
               ^^^^^^^^^^^^^^^^^^^^^^^^^^^^^^^^^^^^^^^^
  File "e:\python_project\chrome_plugin\venv\Lib\site-packages\httpx\_client.py", line 1776, in _send_single_request
    response = await transport.handle_async_request(request)
               ^^^^^^^^^^^^^^^^^^^^^^^^^^^^^^^^^^^^^^^^^^^^^
  File "e:\python_project\chrome_plugin\venv\Lib\site-packages\httpx\_transports\default.py", line 376, in handle_async_request
    with map_httpcore_exceptions():
         ~~~~~~~~~~~~~~~~~~~~~~~^^
  File "C:\Python313\Lib\contextlib.py", line 162, in __exit__
    self.gen.throw(value)
    ~~~~~~~~~~~~~~^^^^^^^
  File "e:\python_project\chrome_plugin\venv\Lib\site-packages\httpx\_transports\default.py", line 89, in map_httpcore_exceptions
    raise mapped_exc(message) from exc
httpx.UnsupportedProtocol: Request URL is missing an 'http://' or 'https://' protocol.

2025-10-23 01:54:18,214 - f2 - ERROR - httpx 请求错误：file_hash，错误详情：Request URL is missing an 'http://' or 'https://' protocol.
2025-10-23 01:54:18,215 - f2 - WARNING - 链接 file_hash 响应大小为 0 字节，尝试下一个链接是否可用
2025-10-23 01:54:18,518 - f2 - ERROR - Traceback (most recent call last):
  File "e:\python_project\chrome_plugin\venv\Lib\site-packages\httpx\_transports\default.py", line 72, in map_httpcore_exceptions
    yield
  File "e:\python_project\chrome_plugin\venv\Lib\site-packages\httpx\_transports\default.py", line 377, in handle_async_request
    resp = await self._pool.handle_async_request(req)
           ^^^^^^^^^^^^^^^^^^^^^^^^^^^^^^^^^^^^^^^^^^
  File "e:\python_project\chrome_plugin\venv\Lib\site-packages\httpcore\_async\connection_pool.py", line 207, in handle_async_request
    raise UnsupportedProtocol(
        "Request URL is missing an 'http://' or 'https://' protocol."
    )
httpcore.UnsupportedProtocol: Request URL is missing an 'http://' or 'https://' protocol.

The above exception was the direct cause of the following exception:

Traceback (most recent call last):
  File "e:\python_project\chrome_plugin\venv\Lib\site-packages\f2\utils\_dl.py", line 40, in get_content_length
    response = await aclient.head(url, headers=headers, follow_redirects=True)
               ^^^^^^^^^^^^^^^^^^^^^^^^^^^^^^^^^^^^^^^^^^^^^^^^^^^^^^^^^^^^^^^
  File "e:\python_project\chrome_plugin\venv\Lib\site-packages\httpx\_client.py", line 1872, in head
    return await self.request(
           ^^^^^^^^^^^^^^^^^^^
    ...<9 lines>...
    )
    ^
  File "e:\python_project\chrome_plugin\venv\Lib\site-packages\httpx\_client.py", line 1585, in request
    return await self.send(request, auth=auth, follow_redirects=follow_redirects)
           ^^^^^^^^^^^^^^^^^^^^^^^^^^^^^^^^^^^^^^^^^^^^^^^^^^^^^^^^^^^^^^^^^^^^^^
  File "e:\python_project\chrome_plugin\venv\Lib\site-packages\httpx\_client.py", line 1674, in send
    response = await self._send_handling_auth(
               ^^^^^^^^^^^^^^^^^^^^^^^^^^^^^^^
    ...<4 lines>...
    )
    ^
  File "e:\python_project\chrome_plugin\venv\Lib\site-packages\httpx\_client.py", line 1702, in _send_handling_auth
    response = await self._send_handling_redirects(
               ^^^^^^^^^^^^^^^^^^^^^^^^^^^^^^^^^^^^
    ...<3 lines>...
    )
    ^
  File "e:\python_project\chrome_plugin\venv\Lib\site-packages\httpx\_client.py", line 1739, in _send_handling_redirects
    response = await self._send_single_request(request)
               ^^^^^^^^^^^^^^^^^^^^^^^^^^^^^^^^^^^^^^^^
  File "e:\python_project\chrome_plugin\venv\Lib\site-packages\httpx\_client.py", line 1776, in _send_single_request
    response = await transport.handle_async_request(request)
               ^^^^^^^^^^^^^^^^^^^^^^^^^^^^^^^^^^^^^^^^^^^^^
  File "e:\python_project\chrome_plugin\venv\Lib\site-packages\httpx\_transports\default.py", line 376, in handle_async_request
    with map_httpcore_exceptions():
         ~~~~~~~~~~~~~~~~~~~~~~~^^
  File "C:\Python313\Lib\contextlib.py", line 162, in __exit__
    self.gen.throw(value)
    ~~~~~~~~~~~~~~^^^^^^^
  File "e:\python_project\chrome_plugin\venv\Lib\site-packages\httpx\_transports\default.py", line 89, in map_httpcore_exceptions
    raise mapped_exc(message) from exc
httpx.UnsupportedProtocol: Request URL is missing an 'http://' or 'https://' protocol.

2025-10-23 01:54:18,525 - f2 - ERROR - httpx 请求错误：height，错误详情：Request URL is missing an 'http://' or 'https://' protocol.
2025-10-23 01:54:18,527 - f2 - WARNING - 链接 height 响应大小为 0 字节，尝试下一个链接是否可用
2025-10-23 01:54:18,817 - f2 - ERROR - Traceback (most recent call last):
  File "e:\python_project\chrome_plugin\venv\Lib\site-packages\httpx\_transports\default.py", line 72, in map_httpcore_exceptions
    yield
  File "e:\python_project\chrome_plugin\venv\Lib\site-packages\httpx\_transports\default.py", line 377, in handle_async_request
    resp = await self._pool.handle_async_request(req)
           ^^^^^^^^^^^^^^^^^^^^^^^^^^^^^^^^^^^^^^^^^^
  File "e:\python_project\chrome_plugin\venv\Lib\site-packages\httpcore\_async\connection_pool.py", line 207, in handle_async_request
    raise UnsupportedProtocol(
        "Request URL is missing an 'http://' or 'https://' protocol."
    )
httpcore.UnsupportedProtocol: Request URL is missing an 'http://' or 'https://' protocol.

The above exception was the direct cause of the following exception:

Traceback (most recent call last):
  File "e:\python_project\chrome_plugin\venv\Lib\site-packages\f2\utils\_dl.py", line 40, in get_content_length
    response = await aclient.head(url, headers=headers, follow_redirects=True)
               ^^^^^^^^^^^^^^^^^^^^^^^^^^^^^^^^^^^^^^^^^^^^^^^^^^^^^^^^^^^^^^^
  File "e:\python_project\chrome_plugin\venv\Lib\site-packages\httpx\_client.py", line 1872, in head
    return await self.request(
           ^^^^^^^^^^^^^^^^^^^
    ...<9 lines>...
    )
    ^
  File "e:\python_project\chrome_plugin\venv\Lib\site-packages\httpx\_client.py", line 1585, in request
    return await self.send(request, auth=auth, follow_redirects=follow_redirects)
           ^^^^^^^^^^^^^^^^^^^^^^^^^^^^^^^^^^^^^^^^^^^^^^^^^^^^^^^^^^^^^^^^^^^^^^
  File "e:\python_project\chrome_plugin\venv\Lib\site-packages\httpx\_client.py", line 1674, in send
    response = await self._send_handling_auth(
               ^^^^^^^^^^^^^^^^^^^^^^^^^^^^^^^
    ...<4 lines>...
    )
    ^
  File "e:\python_project\chrome_plugin\venv\Lib\site-packages\httpx\_client.py", line 1702, in _send_handling_auth
    response = await self._send_handling_redirects(
               ^^^^^^^^^^^^^^^^^^^^^^^^^^^^^^^^^^^^
    ...<3 lines>...
    )
    ^
  File "e:\python_project\chrome_plugin\venv\Lib\site-packages\httpx\_client.py", line 1739, in _send_handling_redirects
    response = await self._send_single_request(request)
               ^^^^^^^^^^^^^^^^^^^^^^^^^^^^^^^^^^^^^^^^
  File "e:\python_project\chrome_plugin\venv\Lib\site-packages\httpx\_client.py", line 1776, in _send_single_request
    response = await transport.handle_async_request(request)
               ^^^^^^^^^^^^^^^^^^^^^^^^^^^^^^^^^^^^^^^^^^^^^
  File "e:\python_project\chrome_plugin\venv\Lib\site-packages\httpx\_transports\default.py", line 376, in handle_async_request
    with map_httpcore_exceptions():
         ~~~~~~~~~~~~~~~~~~~~~~~^^
  File "C:\Python313\Lib\contextlib.py", line 162, in __exit__
    self.gen.throw(value)
    ~~~~~~~~~~~~~~^^^^^^^
  File "e:\python_project\chrome_plugin\venv\Lib\site-packages\httpx\_transports\default.py", line 89, in map_httpcore_exceptions
    raise mapped_exc(message) from exc
httpx.UnsupportedProtocol: Request URL is missing an 'http://' or 'https://' protocol.

2025-10-23 01:54:18,832 - f2 - ERROR - httpx 请求错误：uri，错误详情：Request URL is missing an 'http://' or 'https://' protocol.
2025-10-23 01:54:18,833 - f2 - WARNING - 链接 uri 响应大小为 0 字节，尝试下一个链接是否可用
2025-10-23 01:54:19,124 - f2 - ERROR - Traceback (most recent call last):
  File "e:\python_project\chrome_plugin\venv\Lib\site-packages\httpx\_transports\default.py", line 72, in map_httpcore_exceptions
    yield
  File "e:\python_project\chrome_plugin\venv\Lib\site-packages\httpx\_transports\default.py", line 377, in handle_async_request
    resp = await self._pool.handle_async_request(req)
           ^^^^^^^^^^^^^^^^^^^^^^^^^^^^^^^^^^^^^^^^^^
  File "e:\python_project\chrome_plugin\venv\Lib\site-packages\httpcore\_async\connection_pool.py", line 207, in handle_async_request
    raise UnsupportedProtocol(
        "Request URL is missing an 'http://' or 'https://' protocol."
    )
httpcore.UnsupportedProtocol: Request URL is missing an 'http://' or 'https://' protocol.

The above exception was the direct cause of the following exception:

Traceback (most recent call last):
  File "e:\python_project\chrome_plugin\venv\Lib\site-packages\f2\utils\_dl.py", line 40, in get_content_length
    response = await aclient.head(url, headers=headers, follow_redirects=True)
               ^^^^^^^^^^^^^^^^^^^^^^^^^^^^^^^^^^^^^^^^^^^^^^^^^^^^^^^^^^^^^^^
  File "e:\python_project\chrome_plugin\venv\Lib\site-packages\httpx\_client.py", line 1872, in head
    return await self.request(
           ^^^^^^^^^^^^^^^^^^^
    ...<9 lines>...
    )
    ^
  File "e:\python_project\chrome_plugin\venv\Lib\site-packages\httpx\_client.py", line 1585, in request
    return await self.send(request, auth=auth, follow_redirects=follow_redirects)
           ^^^^^^^^^^^^^^^^^^^^^^^^^^^^^^^^^^^^^^^^^^^^^^^^^^^^^^^^^^^^^^^^^^^^^^
  File "e:\python_project\chrome_plugin\venv\Lib\site-packages\httpx\_client.py", line 1674, in send
    response = await self._send_handling_auth(
               ^^^^^^^^^^^^^^^^^^^^^^^^^^^^^^^
    ...<4 lines>...
    )
    ^
  File "e:\python_project\chrome_plugin\venv\Lib\site-packages\httpx\_client.py", line 1702, in _send_handling_auth
    response = await self._send_handling_redirects(
               ^^^^^^^^^^^^^^^^^^^^^^^^^^^^^^^^^^^^
    ...<3 lines>...
    )
    ^
  File "e:\python_project\chrome_plugin\venv\Lib\site-packages\httpx\_client.py", line 1739, in _send_handling_redirects
    response = await self._send_single_request(request)
               ^^^^^^^^^^^^^^^^^^^^^^^^^^^^^^^^^^^^^^^^
  File "e:\python_project\chrome_plugin\venv\Lib\site-packages\httpx\_client.py", line 1776, in _send_single_request
    response = await transport.handle_async_request(request)
               ^^^^^^^^^^^^^^^^^^^^^^^^^^^^^^^^^^^^^^^^^^^^^
  File "e:\python_project\chrome_plugin\venv\Lib\site-packages\httpx\_transports\default.py", line 376, in handle_async_request
    with map_httpcore_exceptions():
         ~~~~~~~~~~~~~~~~~~~~~~~^^
  File "C:\Python313\Lib\contextlib.py", line 162, in __exit__
    self.gen.throw(value)
    ~~~~~~~~~~~~~~^^^^^^^
  File "e:\python_project\chrome_plugin\venv\Lib\site-packages\httpx\_transports\default.py", line 89, in map_httpcore_exceptions
    raise mapped_exc(message) from exc
httpx.UnsupportedProtocol: Request URL is missing an 'http://' or 'https://' protocol.

2025-10-23 01:54:19,129 - f2 - ERROR - httpx 请求错误：url_key，错误详情：Request URL is missing an 'http://' or 'https://' protocol.
2025-10-23 01:54:19,130 - f2 - WARNING - 链接 url_key 响应大小为 0 字节，尝试下一个链接是否可用
2025-10-23 01:54:19,424 - f2 - ERROR - Traceback (most recent call last):
  File "e:\python_project\chrome_plugin\venv\Lib\site-packages\httpx\_transports\default.py", line 72, in map_httpcore_exceptions
    yield
  File "e:\python_project\chrome_plugin\venv\Lib\site-packages\httpx\_transports\default.py", line 377, in handle_async_request
    resp = await self._pool.handle_async_request(req)
           ^^^^^^^^^^^^^^^^^^^^^^^^^^^^^^^^^^^^^^^^^^
  File "e:\python_project\chrome_plugin\venv\Lib\site-packages\httpcore\_async\connection_pool.py", line 207, in handle_async_request
    raise UnsupportedProtocol(
        "Request URL is missing an 'http://' or 'https://' protocol."
    )
httpcore.UnsupportedProtocol: Request URL is missing an 'http://' or 'https://' protocol.

The above exception was the direct cause of the following exception:

Traceback (most recent call last):
  File "e:\python_project\chrome_plugin\venv\Lib\site-packages\f2\utils\_dl.py", line 40, in get_content_length
    response = await aclient.head(url, headers=headers, follow_redirects=True)
               ^^^^^^^^^^^^^^^^^^^^^^^^^^^^^^^^^^^^^^^^^^^^^^^^^^^^^^^^^^^^^^^
  File "e:\python_project\chrome_plugin\venv\Lib\site-packages\httpx\_client.py", line 1872, in head
    return await self.request(
           ^^^^^^^^^^^^^^^^^^^
    ...<9 lines>...
    )
    ^
  File "e:\python_project\chrome_plugin\venv\Lib\site-packages\httpx\_client.py", line 1585, in request
    return await self.send(request, auth=auth, follow_redirects=follow_redirects)
           ^^^^^^^^^^^^^^^^^^^^^^^^^^^^^^^^^^^^^^^^^^^^^^^^^^^^^^^^^^^^^^^^^^^^^^
  File "e:\python_project\chrome_plugin\venv\Lib\site-packages\httpx\_client.py", line 1674, in send
    response = await self._send_handling_auth(
               ^^^^^^^^^^^^^^^^^^^^^^^^^^^^^^^
    ...<4 lines>...
    )
    ^
  File "e:\python_project\chrome_plugin\venv\Lib\site-packages\httpx\_client.py", line 1702, in _send_handling_auth
    response = await self._send_handling_redirects(
               ^^^^^^^^^^^^^^^^^^^^^^^^^^^^^^^^^^^^
    ...<3 lines>...
    )
    ^
  File "e:\python_project\chrome_plugin\venv\Lib\site-packages\httpx\_client.py", line 1739, in _send_handling_redirects
    response = await self._send_single_request(request)
               ^^^^^^^^^^^^^^^^^^^^^^^^^^^^^^^^^^^^^^^^
  File "e:\python_project\chrome_plugin\venv\Lib\site-packages\httpx\_client.py", line 1776, in _send_single_request
    response = await transport.handle_async_request(request)
               ^^^^^^^^^^^^^^^^^^^^^^^^^^^^^^^^^^^^^^^^^^^^^
  File "e:\python_project\chrome_plugin\venv\Lib\site-packages\httpx\_transports\default.py", line 376, in handle_async_request
    with map_httpcore_exceptions():
         ~~~~~~~~~~~~~~~~~~~~~~~^^
  File "C:\Python313\Lib\contextlib.py", line 162, in __exit__
    self.gen.throw(value)
    ~~~~~~~~~~~~~~^^^^^^^
  File "e:\python_project\chrome_plugin\venv\Lib\site-packages\httpx\_transports\default.py", line 89, in map_httpcore_exceptions
    raise mapped_exc(message) from exc
httpx.UnsupportedProtocol: Request URL is missing an 'http://' or 'https://' protocol.

2025-10-23 01:54:19,428 - f2 - ERROR - httpx 请求错误：url_list，错误详情：Request URL is missing an 'http://' or 'https://' protocol.
2025-10-23 01:54:19,430 - f2 - WARNING - 链接 url_list 响应大小为 0 字节，尝试下一个链接是否可用
2025-10-23 01:54:19,717 - f2 - ERROR - Traceback (most recent call last):
  File "e:\python_project\chrome_plugin\venv\Lib\site-packages\httpx\_transports\default.py", line 72, in map_httpcore_exceptions
    yield
  File "e:\python_project\chrome_plugin\venv\Lib\site-packages\httpx\_transports\default.py", line 377, in handle_async_request
    resp = await self._pool.handle_async_request(req)
           ^^^^^^^^^^^^^^^^^^^^^^^^^^^^^^^^^^^^^^^^^^
  File "e:\python_project\chrome_plugin\venv\Lib\site-packages\httpcore\_async\connection_pool.py", line 207, in handle_async_request
    raise UnsupportedProtocol(
        "Request URL is missing an 'http://' or 'https://' protocol."
    )
httpcore.UnsupportedProtocol: Request URL is missing an 'http://' or 'https://' protocol.

The above exception was the direct cause of the following exception:

Traceback (most recent call last):
  File "e:\python_project\chrome_plugin\venv\Lib\site-packages\f2\utils\_dl.py", line 40, in get_content_length
    response = await aclient.head(url, headers=headers, follow_redirects=True)
               ^^^^^^^^^^^^^^^^^^^^^^^^^^^^^^^^^^^^^^^^^^^^^^^^^^^^^^^^^^^^^^^
  File "e:\python_project\chrome_plugin\venv\Lib\site-packages\httpx\_client.py", line 1872, in head
    return await self.request(
           ^^^^^^^^^^^^^^^^^^^
    ...<9 lines>...
    )
    ^
  File "e:\python_project\chrome_plugin\venv\Lib\site-packages\httpx\_client.py", line 1585, in request
    return await self.send(request, auth=auth, follow_redirects=follow_redirects)
           ^^^^^^^^^^^^^^^^^^^^^^^^^^^^^^^^^^^^^^^^^^^^^^^^^^^^^^^^^^^^^^^^^^^^^^
  File "e:\python_project\chrome_plugin\venv\Lib\site-packages\httpx\_client.py", line 1674, in send
    response = await self._send_handling_auth(
               ^^^^^^^^^^^^^^^^^^^^^^^^^^^^^^^
    ...<4 lines>...
    )
    ^
  File "e:\python_project\chrome_plugin\venv\Lib\site-packages\httpx\_client.py", line 1702, in _send_handling_auth
    response = await self._send_handling_redirects(
               ^^^^^^^^^^^^^^^^^^^^^^^^^^^^^^^^^^^^
    ...<3 lines>...
    )
    ^
  File "e:\python_project\chrome_plugin\venv\Lib\site-packages\httpx\_client.py", line 1739, in _send_handling_redirects
    response = await self._send_single_request(request)
               ^^^^^^^^^^^^^^^^^^^^^^^^^^^^^^^^^^^^^^^^
  File "e:\python_project\chrome_plugin\venv\Lib\site-packages\httpx\_client.py", line 1776, in _send_single_request
    response = await transport.handle_async_request(request)
               ^^^^^^^^^^^^^^^^^^^^^^^^^^^^^^^^^^^^^^^^^^^^^
  File "e:\python_project\chrome_plugin\venv\Lib\site-packages\httpx\_transports\default.py", line 376, in handle_async_request
    with map_httpcore_exceptions():
         ~~~~~~~~~~~~~~~~~~~~~~~^^
  File "C:\Python313\Lib\contextlib.py", line 162, in __exit__
    self.gen.throw(value)
    ~~~~~~~~~~~~~~^^^^^^^
  File "e:\python_project\chrome_plugin\venv\Lib\site-packages\httpx\_transports\default.py", line 89, in map_httpcore_exceptions
    raise mapped_exc(message) from exc
httpx.UnsupportedProtocol: Request URL is missing an 'http://' or 'https://' protocol.

2025-10-23 01:54:19,723 - f2 - ERROR - httpx 请求错误：width，错误详情：Request URL is missing an 'http://' or 'https://' protocol.
2025-10-23 01:54:19,725 - f2 - WARNING - 链接 width 响应大小为 0 字节，尝试下一个链接是否可用
2025-10-23 01:54:19,726 - f2 - WARNING - 所有链接都无法下载
2025-10-23 01:54:19,727 - f2 - ERROR - [red][  丢失  ]：[/red]无法下载文件：7563576129932496137_video.mp4
